try{
    console.log(a+b)
}
catch(err){
    console.log(err)
    console.log("Error found")
    console.log("Error saved in error log")
}
console.log("Program execution continues")
